[2024-08-23T11:12:21.462+0200] {taskinstance.py:1957} INFO - Dependencies all met for dep_context=non-requeueable deps ti=<TaskInstance: Ugoo-DAG.download scheduled__2024-08-23T08:00:00+00:00 [queued]>
[2024-08-23T11:12:21.497+0200] {taskinstance.py:1957} INFO - Dependencies all met for dep_context=requeueable deps ti=<TaskInstance: Ugoo-DAG.download scheduled__2024-08-23T08:00:00+00:00 [queued]>
[2024-08-23T11:12:21.497+0200] {taskinstance.py:2171} INFO - Starting attempt 1 of 2
[2024-08-23T11:12:21.566+0200] {taskinstance.py:2192} INFO - Executing <Task(PythonOperator): download> on 2024-08-23 08:00:00+00:00
[2024-08-23T11:12:21.571+0200] {standard_task_runner.py:60} INFO - Started process 103186 to run task
[2024-08-23T11:12:21.585+0200] {standard_task_runner.py:87} INFO - Running: ['airflow', 'tasks', 'run', 'Ugoo-DAG', 'download', 'scheduled__2024-08-23T08:00:00+00:00', '--job-id', '1249', '--raw', '--subdir', 'DAGS_FOLDER/datadownload.py', '--cfg-path', '/tmp/tmpe7pak68e']
[2024-08-23T11:12:21.594+0200] {standard_task_runner.py:88} INFO - Job 1249: Subtask download
[2024-08-23T11:12:21.669+0200] {task_command.py:423} INFO - Running <TaskInstance: Ugoo-DAG.download scheduled__2024-08-23T08:00:00+00:00 [running]> on host Ugoo.
[2024-08-23T11:12:21.812+0200] {taskinstance.py:2481} INFO - Exporting env vars: AIRFLOW_CTX_DAG_EMAIL='ugoo@ezekomas.com' AIRFLOW_CTX_DAG_OWNER='Ugoo Ezekoma' AIRFLOW_CTX_DAG_ID='Ugoo-DAG' AIRFLOW_CTX_TASK_ID='download' AIRFLOW_CTX_EXECUTION_DATE='2024-08-23T08:00:00+00:00' AIRFLOW_CTX_TRY_NUMBER='1' AIRFLOW_CTX_DAG_RUN_ID='scheduled__2024-08-23T08:00:00+00:00'
[2024-08-23T13:43:38.093+0200] {local_task_job_runner.py:211} ERROR - Heartbeat time limit exceeded!
[2024-08-23T13:43:38.114+0200] {process_utils.py:131} INFO - Sending Signals.SIGTERM to group 103186. PIDs of all processes in the group: [103186]
[2024-08-23T13:43:38.116+0200] {process_utils.py:86} INFO - Sending the signal Signals.SIGTERM to group 103186
[2024-08-23T13:43:38.130+0200] {taskinstance.py:2451} ERROR - Received SIGTERM. Terminating subprocesses.
[2024-08-23T13:43:38.250+0200] {taskinstance.py:2699} ERROR - Task failed with exception
Traceback (most recent call last):
  File "/home/ugoo/airflow_env/lib/python3.10/site-packages/airflow/models/taskinstance.py", line 433, in _execute_task
    result = execute_callable(context=context, **execute_callable_kwargs)
  File "/home/ugoo/airflow_env/lib/python3.10/site-packages/airflow/operators/python.py", line 199, in execute
    return_value = self.execute_callable()
  File "/home/ugoo/airflow_env/lib/python3.10/site-packages/airflow/operators/python.py", line 216, in execute_callable
    return self.python_callable(*self.op_args, **self.op_kwargs)
  File "/home/ugoo/airflow/dags/datadownload.py", line 21, in download
    response = requests.get(url)
  File "/home/ugoo/airflow_env/lib/python3.10/site-packages/requests/api.py", line 73, in get
    return request("get", url, params=params, **kwargs)
  File "/home/ugoo/airflow_env/lib/python3.10/site-packages/requests/api.py", line 59, in request
    return session.request(method=method, url=url, **kwargs)
  File "/home/ugoo/airflow_env/lib/python3.10/site-packages/requests/sessions.py", line 589, in request
    resp = self.send(prep, **send_kwargs)
  File "/home/ugoo/airflow_env/lib/python3.10/site-packages/requests/sessions.py", line 703, in send
    r = adapter.send(request, **kwargs)
  File "/home/ugoo/airflow_env/lib/python3.10/site-packages/requests/adapters.py", line 486, in send
    resp = conn.urlopen(
  File "/home/ugoo/airflow_env/lib/python3.10/site-packages/urllib3/connectionpool.py", line 790, in urlopen
    response = self._make_request(
  File "/home/ugoo/airflow_env/lib/python3.10/site-packages/urllib3/connectionpool.py", line 536, in _make_request
    response = conn.getresponse()
  File "/home/ugoo/airflow_env/lib/python3.10/site-packages/urllib3/connection.py", line 461, in getresponse
    httplib_response = super().getresponse()
  File "/usr/lib/python3.10/http/client.py", line 1375, in getresponse
    response.begin()
  File "/usr/lib/python3.10/http/client.py", line 318, in begin
    version, status, reason = self._read_status()
  File "/usr/lib/python3.10/http/client.py", line 279, in _read_status
    line = str(self.fp.readline(_MAXLINE + 1), "iso-8859-1")
  File "/usr/lib/python3.10/socket.py", line 705, in readinto
    return self._sock.recv_into(b)
  File "/usr/lib/python3.10/ssl.py", line 1303, in recv_into
    return self.read(nbytes, buffer)
  File "/usr/lib/python3.10/ssl.py", line 1159, in read
    return self._sslobj.read(len, buffer)
  File "/home/ugoo/airflow_env/lib/python3.10/site-packages/airflow/models/taskinstance.py", line 2453, in signal_handler
    raise AirflowException("Task received SIGTERM signal")
airflow.exceptions.AirflowException: Task received SIGTERM signal
[2024-08-23T13:43:38.296+0200] {taskinstance.py:1138} INFO - Marking task as UP_FOR_RETRY. dag_id=Ugoo-DAG, task_id=download, execution_date=20240823T080000, start_date=20240823T091221, end_date=20240823T114338
[2024-08-23T13:43:39.120+0200] {logging_mixin.py:188} WARNING - /home/ugoo/airflow_env/lib/python3.10/site-packages/airflow/utils/email.py:154 RemovedInAirflow3Warning: Fetching SMTP credentials from configuration variables will be deprecated in a future release. Please set credentials using a connection instead.
[2024-08-23T13:43:39.122+0200] {configuration.py:1046} WARNING - section/key [smtp/smtp_user] not found in config
[2024-08-23T13:43:39.123+0200] {email.py:270} INFO - Email alerting: attempt 1
[2024-08-23T13:43:39.163+0200] {configuration.py:1046} WARNING - section/key [smtp/smtp_user] not found in config
[2024-08-23T13:43:39.163+0200] {email.py:270} INFO - Email alerting: attempt 1
[2024-08-23T13:43:39.164+0200] {taskinstance.py:826} ERROR - Failed to send email to: ['ugoo@ezekomas.com']
Traceback (most recent call last):
  File "/home/ugoo/airflow_env/lib/python3.10/site-packages/airflow/models/taskinstance.py", line 2335, in _run_raw_task
    self._execute_task_with_callbacks(context, test_mode, session=session)
  File "/home/ugoo/airflow_env/lib/python3.10/site-packages/airflow/models/taskinstance.py", line 2500, in _execute_task_with_callbacks
    result = self._execute_task(context, task_orig)
  File "/home/ugoo/airflow_env/lib/python3.10/site-packages/airflow/models/taskinstance.py", line 2517, in _execute_task
    return _execute_task(self, context, task_orig)
  File "/home/ugoo/airflow_env/lib/python3.10/site-packages/airflow/models/taskinstance.py", line 433, in _execute_task
    result = execute_callable(context=context, **execute_callable_kwargs)
  File "/home/ugoo/airflow_env/lib/python3.10/site-packages/airflow/operators/python.py", line 199, in execute
    return_value = self.execute_callable()
  File "/home/ugoo/airflow_env/lib/python3.10/site-packages/airflow/operators/python.py", line 216, in execute_callable
    return self.python_callable(*self.op_args, **self.op_kwargs)
  File "/home/ugoo/airflow/dags/datadownload.py", line 21, in download
    response = requests.get(url)
  File "/home/ugoo/airflow_env/lib/python3.10/site-packages/requests/api.py", line 73, in get
    return request("get", url, params=params, **kwargs)
  File "/home/ugoo/airflow_env/lib/python3.10/site-packages/requests/api.py", line 59, in request
    return session.request(method=method, url=url, **kwargs)
  File "/home/ugoo/airflow_env/lib/python3.10/site-packages/requests/sessions.py", line 589, in request
    resp = self.send(prep, **send_kwargs)
  File "/home/ugoo/airflow_env/lib/python3.10/site-packages/requests/sessions.py", line 703, in send
    r = adapter.send(request, **kwargs)
  File "/home/ugoo/airflow_env/lib/python3.10/site-packages/requests/adapters.py", line 486, in send
    resp = conn.urlopen(
  File "/home/ugoo/airflow_env/lib/python3.10/site-packages/urllib3/connectionpool.py", line 790, in urlopen
    response = self._make_request(
  File "/home/ugoo/airflow_env/lib/python3.10/site-packages/urllib3/connectionpool.py", line 536, in _make_request
    response = conn.getresponse()
  File "/home/ugoo/airflow_env/lib/python3.10/site-packages/urllib3/connection.py", line 461, in getresponse
    httplib_response = super().getresponse()
  File "/usr/lib/python3.10/http/client.py", line 1375, in getresponse
    response.begin()
  File "/usr/lib/python3.10/http/client.py", line 318, in begin
    version, status, reason = self._read_status()
  File "/usr/lib/python3.10/http/client.py", line 279, in _read_status
    line = str(self.fp.readline(_MAXLINE + 1), "iso-8859-1")
  File "/usr/lib/python3.10/socket.py", line 705, in readinto
    return self._sock.recv_into(b)
  File "/usr/lib/python3.10/ssl.py", line 1303, in recv_into
    return self.read(nbytes, buffer)
  File "/usr/lib/python3.10/ssl.py", line 1159, in read
    return self._sslobj.read(len, buffer)
  File "/home/ugoo/airflow_env/lib/python3.10/site-packages/airflow/models/taskinstance.py", line 2453, in signal_handler
    raise AirflowException("Task received SIGTERM signal")
airflow.exceptions.AirflowException: Task received SIGTERM signal

During handling of the above exception, another exception occurred:

Traceback (most recent call last):
  File "/home/ugoo/airflow_env/lib/python3.10/site-packages/airflow/models/taskinstance.py", line 1000, in _email_alert
    send_email(task.email, subject, html_content)
  File "/home/ugoo/airflow_env/lib/python3.10/site-packages/airflow/utils/email.py", line 80, in send_email
    return backend(
  File "/home/ugoo/airflow_env/lib/python3.10/site-packages/airflow/utils/email.py", line 154, in send_email_smtp
    send_mime_email(e_from=mail_from, e_to=recipients, mime_msg=msg, conn_id=conn_id, dryrun=dryrun)
  File "/home/ugoo/airflow_env/lib/python3.10/site-packages/airflow/utils/email.py", line 272, in send_mime_email
    smtp_conn = _get_smtp_connection(smtp_host, smtp_port, smtp_timeout, smtp_ssl)
  File "/home/ugoo/airflow_env/lib/python3.10/site-packages/airflow/utils/email.py", line 316, in _get_smtp_connection
    return smtplib.SMTP(host=host, port=port, timeout=timeout)
  File "/usr/lib/python3.10/smtplib.py", line 255, in __init__
    (code, msg) = self.connect(host, port)
  File "/usr/lib/python3.10/smtplib.py", line 341, in connect
    self.sock = self._get_socket(host, port, self.timeout)
  File "/usr/lib/python3.10/smtplib.py", line 312, in _get_socket
    return socket.create_connection((host, port), timeout,
  File "/usr/lib/python3.10/socket.py", line 845, in create_connection
    raise err
  File "/usr/lib/python3.10/socket.py", line 833, in create_connection
    sock.connect(sa)
ConnectionRefusedError: [Errno 111] Connection refused

During handling of the above exception, another exception occurred:

Traceback (most recent call last):
  File "/home/ugoo/airflow_env/lib/python3.10/site-packages/airflow/models/taskinstance.py", line 824, in _handle_failure
    task_instance.email_alert(error, failure_context["task"])
  File "/home/ugoo/airflow_env/lib/python3.10/site-packages/airflow/models/taskinstance.py", line 2947, in email_alert
    _email_alert(task_instance=self, exception=exception, task=task)
  File "/home/ugoo/airflow_env/lib/python3.10/site-packages/airflow/models/taskinstance.py", line 1002, in _email_alert
    send_email(task.email, subject, html_content_err)
  File "/home/ugoo/airflow_env/lib/python3.10/site-packages/airflow/utils/email.py", line 80, in send_email
    return backend(
  File "/home/ugoo/airflow_env/lib/python3.10/site-packages/airflow/utils/email.py", line 154, in send_email_smtp
    send_mime_email(e_from=mail_from, e_to=recipients, mime_msg=msg, conn_id=conn_id, dryrun=dryrun)
  File "/home/ugoo/airflow_env/lib/python3.10/site-packages/airflow/utils/email.py", line 272, in send_mime_email
    smtp_conn = _get_smtp_connection(smtp_host, smtp_port, smtp_timeout, smtp_ssl)
  File "/home/ugoo/airflow_env/lib/python3.10/site-packages/airflow/utils/email.py", line 316, in _get_smtp_connection
    return smtplib.SMTP(host=host, port=port, timeout=timeout)
  File "/usr/lib/python3.10/smtplib.py", line 255, in __init__
    (code, msg) = self.connect(host, port)
  File "/usr/lib/python3.10/smtplib.py", line 341, in connect
    self.sock = self._get_socket(host, port, self.timeout)
  File "/usr/lib/python3.10/smtplib.py", line 312, in _get_socket
    return socket.create_connection((host, port), timeout,
  File "/usr/lib/python3.10/socket.py", line 845, in create_connection
    raise err
  File "/usr/lib/python3.10/socket.py", line 833, in create_connection
    sock.connect(sa)
ConnectionRefusedError: [Errno 111] Connection refused
[2024-08-23T13:43:40.621+0200] {standard_task_runner.py:107} ERROR - Failed to execute job 1249 for task download (Task received SIGTERM signal; 103186)
[2024-08-23T13:43:40.651+0200] {process_utils.py:79} INFO - Process psutil.Process(pid=103186, status='terminated', exitcode=1, started='11:12:21') (103186) terminated with exit code 1
