[2024-08-23T19:51:33.453+0200] {taskinstance.py:1957} INFO - Dependencies all met for dep_context=non-requeueable deps ti=<TaskInstance: Ugoo-DAG.download scheduled__2024-08-23T15:00:00+00:00 [queued]>
[2024-08-23T19:51:33.471+0200] {taskinstance.py:1957} INFO - Dependencies all met for dep_context=requeueable deps ti=<TaskInstance: Ugoo-DAG.download scheduled__2024-08-23T15:00:00+00:00 [queued]>
[2024-08-23T19:51:33.471+0200] {taskinstance.py:2171} INFO - Starting attempt 1 of 2
[2024-08-23T19:51:33.497+0200] {taskinstance.py:2192} INFO - Executing <Task(PythonOperator): download> on 2024-08-23 15:00:00+00:00
[2024-08-23T19:51:33.500+0200] {standard_task_runner.py:60} INFO - Started process 124018 to run task
[2024-08-23T19:51:33.503+0200] {standard_task_runner.py:87} INFO - Running: ['airflow', 'tasks', 'run', 'Ugoo-DAG', 'download', 'scheduled__2024-08-23T15:00:00+00:00', '--job-id', '1281', '--raw', '--subdir', 'DAGS_FOLDER/datadownload.py', '--cfg-path', '/tmp/tmpnqdvt8ty']
[2024-08-23T19:51:33.506+0200] {standard_task_runner.py:88} INFO - Job 1281: Subtask download
[2024-08-23T19:51:33.574+0200] {task_command.py:423} INFO - Running <TaskInstance: Ugoo-DAG.download scheduled__2024-08-23T15:00:00+00:00 [running]> on host Ugoo.
[2024-08-23T19:51:33.699+0200] {taskinstance.py:2481} INFO - Exporting env vars: AIRFLOW_CTX_DAG_EMAIL='ugoo@ezekomas.com' AIRFLOW_CTX_DAG_OWNER='Ugoo Ezekoma' AIRFLOW_CTX_DAG_ID='Ugoo-DAG' AIRFLOW_CTX_TASK_ID='download' AIRFLOW_CTX_EXECUTION_DATE='2024-08-23T15:00:00+00:00' AIRFLOW_CTX_TRY_NUMBER='1' AIRFLOW_CTX_DAG_RUN_ID='scheduled__2024-08-23T15:00:00+00:00'
[2024-08-23T23:12:00.236+0200] {logging_mixin.py:188} INFO - Error downloading file: HTTPSConnectionPool(host='cf-courses-data.s3.us.cloud-object-storage.appdomain.cloud', port=443): Read timed out. (read timeout=None)
[2024-08-23T23:12:00.239+0200] {taskinstance.py:2699} ERROR - Task failed with exception
Traceback (most recent call last):
  File "/home/ugoo/airflow_env/lib/python3.10/site-packages/urllib3/connectionpool.py", line 467, in _make_request
    self._validate_conn(conn)
  File "/home/ugoo/airflow_env/lib/python3.10/site-packages/urllib3/connectionpool.py", line 1092, in _validate_conn
    conn.connect()
  File "/home/ugoo/airflow_env/lib/python3.10/site-packages/urllib3/connection.py", line 642, in connect
    sock_and_verified = _ssl_wrap_socket_and_match_hostname(
  File "/home/ugoo/airflow_env/lib/python3.10/site-packages/urllib3/connection.py", line 783, in _ssl_wrap_socket_and_match_hostname
    ssl_sock = ssl_wrap_socket(
  File "/home/ugoo/airflow_env/lib/python3.10/site-packages/urllib3/util/ssl_.py", line 469, in ssl_wrap_socket
    ssl_sock = _ssl_wrap_socket_impl(sock, context, tls_in_tls, server_hostname)
  File "/home/ugoo/airflow_env/lib/python3.10/site-packages/urllib3/util/ssl_.py", line 513, in _ssl_wrap_socket_impl
    return ssl_context.wrap_socket(sock, server_hostname=server_hostname)
  File "/usr/lib/python3.10/ssl.py", line 513, in wrap_socket
    return self.sslsocket_class._create(
  File "/usr/lib/python3.10/ssl.py", line 1100, in _create
    self.do_handshake()
  File "/usr/lib/python3.10/ssl.py", line 1371, in do_handshake
    self._sslobj.do_handshake()
TimeoutError: [Errno 110] Connection timed out

The above exception was the direct cause of the following exception:

Traceback (most recent call last):
  File "/home/ugoo/airflow_env/lib/python3.10/site-packages/requests/adapters.py", line 486, in send
    resp = conn.urlopen(
  File "/home/ugoo/airflow_env/lib/python3.10/site-packages/urllib3/connectionpool.py", line 844, in urlopen
    retries = retries.increment(
  File "/home/ugoo/airflow_env/lib/python3.10/site-packages/urllib3/util/retry.py", line 470, in increment
    raise reraise(type(error), error, _stacktrace)
  File "/home/ugoo/airflow_env/lib/python3.10/site-packages/urllib3/util/util.py", line 39, in reraise
    raise value
  File "/home/ugoo/airflow_env/lib/python3.10/site-packages/urllib3/connectionpool.py", line 790, in urlopen
    response = self._make_request(
  File "/home/ugoo/airflow_env/lib/python3.10/site-packages/urllib3/connectionpool.py", line 491, in _make_request
    raise new_e
  File "/home/ugoo/airflow_env/lib/python3.10/site-packages/urllib3/connectionpool.py", line 469, in _make_request
    self._raise_timeout(err=e, url=url, timeout_value=conn.timeout)
  File "/home/ugoo/airflow_env/lib/python3.10/site-packages/urllib3/connectionpool.py", line 370, in _raise_timeout
    raise ReadTimeoutError(
urllib3.exceptions.ReadTimeoutError: HTTPSConnectionPool(host='cf-courses-data.s3.us.cloud-object-storage.appdomain.cloud', port=443): Read timed out. (read timeout=None)

During handling of the above exception, another exception occurred:

Traceback (most recent call last):
  File "/home/ugoo/airflow_env/lib/python3.10/site-packages/airflow/models/taskinstance.py", line 433, in _execute_task
    result = execute_callable(context=context, **execute_callable_kwargs)
  File "/home/ugoo/airflow_env/lib/python3.10/site-packages/airflow/operators/python.py", line 199, in execute
    return_value = self.execute_callable()
  File "/home/ugoo/airflow_env/lib/python3.10/site-packages/airflow/operators/python.py", line 216, in execute_callable
    return self.python_callable(*self.op_args, **self.op_kwargs)
  File "/home/ugoo/airflow/dags/datadownload.py", line 21, in download
    response = requests.get(url)
  File "/home/ugoo/airflow_env/lib/python3.10/site-packages/requests/api.py", line 73, in get
    return request("get", url, params=params, **kwargs)
  File "/home/ugoo/airflow_env/lib/python3.10/site-packages/requests/api.py", line 59, in request
    return session.request(method=method, url=url, **kwargs)
  File "/home/ugoo/airflow_env/lib/python3.10/site-packages/requests/sessions.py", line 589, in request
    resp = self.send(prep, **send_kwargs)
  File "/home/ugoo/airflow_env/lib/python3.10/site-packages/requests/sessions.py", line 703, in send
    r = adapter.send(request, **kwargs)
  File "/home/ugoo/airflow_env/lib/python3.10/site-packages/requests/adapters.py", line 532, in send
    raise ReadTimeout(e, request=request)
requests.exceptions.ReadTimeout: HTTPSConnectionPool(host='cf-courses-data.s3.us.cloud-object-storage.appdomain.cloud', port=443): Read timed out. (read timeout=None)
[2024-08-23T23:12:00.279+0200] {taskinstance.py:1138} INFO - Marking task as UP_FOR_RETRY. dag_id=Ugoo-DAG, task_id=download, execution_date=20240823T150000, start_date=20240823T175133, end_date=20240823T211200
[2024-08-23T23:12:00.313+0200] {logging_mixin.py:188} WARNING - /home/ugoo/airflow_env/lib/python3.10/site-packages/airflow/utils/email.py:154 RemovedInAirflow3Warning: Fetching SMTP credentials from configuration variables will be deprecated in a future release. Please set credentials using a connection instead.
[2024-08-23T23:12:00.313+0200] {configuration.py:1046} WARNING - section/key [smtp/smtp_user] not found in config
[2024-08-23T23:12:00.313+0200] {email.py:270} INFO - Email alerting: attempt 1
[2024-08-23T23:12:00.315+0200] {configuration.py:1046} WARNING - section/key [smtp/smtp_user] not found in config
[2024-08-23T23:12:00.316+0200] {email.py:270} INFO - Email alerting: attempt 1
[2024-08-23T23:12:00.316+0200] {taskinstance.py:826} ERROR - Failed to send email to: ['ugoo@ezekomas.com']
Traceback (most recent call last):
  File "/home/ugoo/airflow_env/lib/python3.10/site-packages/urllib3/connectionpool.py", line 467, in _make_request
    self._validate_conn(conn)
  File "/home/ugoo/airflow_env/lib/python3.10/site-packages/urllib3/connectionpool.py", line 1092, in _validate_conn
    conn.connect()
  File "/home/ugoo/airflow_env/lib/python3.10/site-packages/urllib3/connection.py", line 642, in connect
    sock_and_verified = _ssl_wrap_socket_and_match_hostname(
  File "/home/ugoo/airflow_env/lib/python3.10/site-packages/urllib3/connection.py", line 783, in _ssl_wrap_socket_and_match_hostname
    ssl_sock = ssl_wrap_socket(
  File "/home/ugoo/airflow_env/lib/python3.10/site-packages/urllib3/util/ssl_.py", line 469, in ssl_wrap_socket
    ssl_sock = _ssl_wrap_socket_impl(sock, context, tls_in_tls, server_hostname)
  File "/home/ugoo/airflow_env/lib/python3.10/site-packages/urllib3/util/ssl_.py", line 513, in _ssl_wrap_socket_impl
    return ssl_context.wrap_socket(sock, server_hostname=server_hostname)
  File "/usr/lib/python3.10/ssl.py", line 513, in wrap_socket
    return self.sslsocket_class._create(
  File "/usr/lib/python3.10/ssl.py", line 1100, in _create
    self.do_handshake()
  File "/usr/lib/python3.10/ssl.py", line 1371, in do_handshake
    self._sslobj.do_handshake()
TimeoutError: [Errno 110] Connection timed out

The above exception was the direct cause of the following exception:

Traceback (most recent call last):
  File "/home/ugoo/airflow_env/lib/python3.10/site-packages/requests/adapters.py", line 486, in send
    resp = conn.urlopen(
  File "/home/ugoo/airflow_env/lib/python3.10/site-packages/urllib3/connectionpool.py", line 844, in urlopen
    retries = retries.increment(
  File "/home/ugoo/airflow_env/lib/python3.10/site-packages/urllib3/util/retry.py", line 470, in increment
    raise reraise(type(error), error, _stacktrace)
  File "/home/ugoo/airflow_env/lib/python3.10/site-packages/urllib3/util/util.py", line 39, in reraise
    raise value
  File "/home/ugoo/airflow_env/lib/python3.10/site-packages/urllib3/connectionpool.py", line 790, in urlopen
    response = self._make_request(
  File "/home/ugoo/airflow_env/lib/python3.10/site-packages/urllib3/connectionpool.py", line 491, in _make_request
    raise new_e
  File "/home/ugoo/airflow_env/lib/python3.10/site-packages/urllib3/connectionpool.py", line 469, in _make_request
    self._raise_timeout(err=e, url=url, timeout_value=conn.timeout)
  File "/home/ugoo/airflow_env/lib/python3.10/site-packages/urllib3/connectionpool.py", line 370, in _raise_timeout
    raise ReadTimeoutError(
urllib3.exceptions.ReadTimeoutError: HTTPSConnectionPool(host='cf-courses-data.s3.us.cloud-object-storage.appdomain.cloud', port=443): Read timed out. (read timeout=None)

During handling of the above exception, another exception occurred:

Traceback (most recent call last):
  File "/home/ugoo/airflow_env/lib/python3.10/site-packages/airflow/models/taskinstance.py", line 2335, in _run_raw_task
    self._execute_task_with_callbacks(context, test_mode, session=session)
  File "/home/ugoo/airflow_env/lib/python3.10/site-packages/airflow/models/taskinstance.py", line 2500, in _execute_task_with_callbacks
    result = self._execute_task(context, task_orig)
  File "/home/ugoo/airflow_env/lib/python3.10/site-packages/airflow/models/taskinstance.py", line 2517, in _execute_task
    return _execute_task(self, context, task_orig)
  File "/home/ugoo/airflow_env/lib/python3.10/site-packages/airflow/models/taskinstance.py", line 433, in _execute_task
    result = execute_callable(context=context, **execute_callable_kwargs)
  File "/home/ugoo/airflow_env/lib/python3.10/site-packages/airflow/operators/python.py", line 199, in execute
    return_value = self.execute_callable()
  File "/home/ugoo/airflow_env/lib/python3.10/site-packages/airflow/operators/python.py", line 216, in execute_callable
    return self.python_callable(*self.op_args, **self.op_kwargs)
  File "/home/ugoo/airflow/dags/datadownload.py", line 21, in download
    response = requests.get(url)
  File "/home/ugoo/airflow_env/lib/python3.10/site-packages/requests/api.py", line 73, in get
    return request("get", url, params=params, **kwargs)
  File "/home/ugoo/airflow_env/lib/python3.10/site-packages/requests/api.py", line 59, in request
    return session.request(method=method, url=url, **kwargs)
  File "/home/ugoo/airflow_env/lib/python3.10/site-packages/requests/sessions.py", line 589, in request
    resp = self.send(prep, **send_kwargs)
  File "/home/ugoo/airflow_env/lib/python3.10/site-packages/requests/sessions.py", line 703, in send
    r = adapter.send(request, **kwargs)
  File "/home/ugoo/airflow_env/lib/python3.10/site-packages/requests/adapters.py", line 532, in send
    raise ReadTimeout(e, request=request)
requests.exceptions.ReadTimeout: HTTPSConnectionPool(host='cf-courses-data.s3.us.cloud-object-storage.appdomain.cloud', port=443): Read timed out. (read timeout=None)

During handling of the above exception, another exception occurred:

Traceback (most recent call last):
  File "/home/ugoo/airflow_env/lib/python3.10/site-packages/airflow/models/taskinstance.py", line 1000, in _email_alert
    send_email(task.email, subject, html_content)
  File "/home/ugoo/airflow_env/lib/python3.10/site-packages/airflow/utils/email.py", line 80, in send_email
    return backend(
  File "/home/ugoo/airflow_env/lib/python3.10/site-packages/airflow/utils/email.py", line 154, in send_email_smtp
    send_mime_email(e_from=mail_from, e_to=recipients, mime_msg=msg, conn_id=conn_id, dryrun=dryrun)
  File "/home/ugoo/airflow_env/lib/python3.10/site-packages/airflow/utils/email.py", line 272, in send_mime_email
    smtp_conn = _get_smtp_connection(smtp_host, smtp_port, smtp_timeout, smtp_ssl)
  File "/home/ugoo/airflow_env/lib/python3.10/site-packages/airflow/utils/email.py", line 316, in _get_smtp_connection
    return smtplib.SMTP(host=host, port=port, timeout=timeout)
  File "/usr/lib/python3.10/smtplib.py", line 255, in __init__
    (code, msg) = self.connect(host, port)
  File "/usr/lib/python3.10/smtplib.py", line 341, in connect
    self.sock = self._get_socket(host, port, self.timeout)
  File "/usr/lib/python3.10/smtplib.py", line 312, in _get_socket
    return socket.create_connection((host, port), timeout,
  File "/usr/lib/python3.10/socket.py", line 845, in create_connection
    raise err
  File "/usr/lib/python3.10/socket.py", line 833, in create_connection
    sock.connect(sa)
ConnectionRefusedError: [Errno 111] Connection refused

During handling of the above exception, another exception occurred:

Traceback (most recent call last):
  File "/home/ugoo/airflow_env/lib/python3.10/site-packages/airflow/models/taskinstance.py", line 824, in _handle_failure
    task_instance.email_alert(error, failure_context["task"])
  File "/home/ugoo/airflow_env/lib/python3.10/site-packages/airflow/models/taskinstance.py", line 2947, in email_alert
    _email_alert(task_instance=self, exception=exception, task=task)
  File "/home/ugoo/airflow_env/lib/python3.10/site-packages/airflow/models/taskinstance.py", line 1002, in _email_alert
    send_email(task.email, subject, html_content_err)
  File "/home/ugoo/airflow_env/lib/python3.10/site-packages/airflow/utils/email.py", line 80, in send_email
    return backend(
  File "/home/ugoo/airflow_env/lib/python3.10/site-packages/airflow/utils/email.py", line 154, in send_email_smtp
    send_mime_email(e_from=mail_from, e_to=recipients, mime_msg=msg, conn_id=conn_id, dryrun=dryrun)
  File "/home/ugoo/airflow_env/lib/python3.10/site-packages/airflow/utils/email.py", line 272, in send_mime_email
    smtp_conn = _get_smtp_connection(smtp_host, smtp_port, smtp_timeout, smtp_ssl)
  File "/home/ugoo/airflow_env/lib/python3.10/site-packages/airflow/utils/email.py", line 316, in _get_smtp_connection
    return smtplib.SMTP(host=host, port=port, timeout=timeout)
  File "/usr/lib/python3.10/smtplib.py", line 255, in __init__
    (code, msg) = self.connect(host, port)
  File "/usr/lib/python3.10/smtplib.py", line 341, in connect
    self.sock = self._get_socket(host, port, self.timeout)
  File "/usr/lib/python3.10/smtplib.py", line 312, in _get_socket
    return socket.create_connection((host, port), timeout,
  File "/usr/lib/python3.10/socket.py", line 845, in create_connection
    raise err
  File "/usr/lib/python3.10/socket.py", line 833, in create_connection
    sock.connect(sa)
ConnectionRefusedError: [Errno 111] Connection refused
[2024-08-23T23:12:00.336+0200] {standard_task_runner.py:107} ERROR - Failed to execute job 1281 for task download (HTTPSConnectionPool(host='cf-courses-data.s3.us.cloud-object-storage.appdomain.cloud', port=443): Read timed out. (read timeout=None); 124018)
[2024-08-23T23:12:00.341+0200] {local_task_job_runner.py:234} INFO - Task exited with return code 1
[2024-08-23T23:12:00.355+0200] {taskinstance.py:3281} INFO - 0 downstream tasks scheduled from follow-on schedule check
